<?xml version="1.0" encoding="UTF-8"?>
<!-- Generated by org.testng.reporters.JUnitXMLReporter -->
<testsuite hostname="AKSHAYJ-Win8" ignored="0" name="Test" tests="8" failures="2" timestamp="28 Mar 2019 05:30:32 GMT" time="0.047" errors="0">
  <testcase name="CanAddNumbers" time="0.006" classname="xray.cloud.test.CalcTest"/>
  <testcase name="CanAddNumbersFromGivenData" time="0.002" classname="xray.cloud.test.CalcTest"/>
  <testcase name="CanAddNumbersFromGivenData" time="0.001" classname="xray.cloud.test.CalcTest">
    <failure type="java.lang.AssertionError" message="expected [4] but found [5]">
      <![CDATA[java.lang.AssertionError: expected [4] but found [5]
	at xray.cloud.test.CalcTest.CanAddNumbersFromGivenData(CalcTest.java:40)
... Removed 31 stack frames]]>
    </failure>
  </testcase> <!-- CanAddNumbersFromGivenData -->
  <testcase name="CanAddNumbersFromGivenData" time="0.001" classname="xray.cloud.test.CalcTest"/>
  <testcase name="CanDivide" time="0.001" classname="xray.cloud.test.CalcTest"/>
  <testcase name="CanDoStuff" time="0.001" classname="xray.cloud.test.CalcTest">
    <failure type="java.lang.AssertionError" message="null">
      <![CDATA[java.lang.AssertionError: null
	at xray.cloud.test.CalcTest.CanDoStuff(CalcTest.java:86)
... Removed 28 stack frames]]>
    </failure>
  </testcase> <!-- CanDoStuff -->
  <testcase name="CanMultiplyX" time="0.001" classname="xray.cloud.test.CalcTest"/>
  <testcase name="CanSubtract" time="0.0" classname="xray.cloud.test.CalcTest"/>
</testsuite> <!-- Test -->
