<?xml version="1.0" encoding="UTF-8"?>
<!-- Generated by org.testng.reporters.JUnitReportReporter -->
<testsuite skipped="0" hostname="AKSHAYJ-Win8" name="xray.cloud.test.CalcTest" tests="8" failures="2" timestamp="28 Mar 2019 05:30:32 GMT" time="0.013" errors="0">
  <testcase name="CanDoStuff" time="0.001" classname="xray.cloud.test.CalcTest">
    <failure type="java.lang.AssertionError" message="null">
      <![CDATA[java.lang.AssertionError: null
	at org.testng.Assert.fail(Assert.java:93)
	at org.testng.Assert.assertNotEquals(Assert.java:897)
	at org.testng.Assert.assertNotEquals(Assert.java:902)
	at xray.cloud.test.CalcTest.CanDoStuff(CalcTest.java:86)
	at sun.reflect.NativeMethodAccessorImpl.invoke0(Native Method)
	at sun.reflect.NativeMethodAccessorImpl.invoke(Unknown Source)
	at sun.reflect.DelegatingMethodAccessorImpl.invoke(Unknown Source)
	at java.lang.reflect.Method.invoke(Unknown Source)
	at org.testng.internal.MethodInvocationHelper.invokeMethod(MethodInvocationHelper.java:108)
	at org.testng.internal.Invoker.invokeMethod(Invoker.java:661)
	at org.testng.internal.Invoker.invokeTestMethod(Invoker.java:869)
	at org.testng.internal.Invoker.invokeTestMethods(Invoker.java:1193)
	at org.testng.internal.TestMethodWorker.invokeTestMethods(TestMethodWorker.java:126)
	at org.testng.internal.TestMethodWorker.run(TestMethodWorker.java:109)
	at org.testng.TestRunner.privateRun(TestRunner.java:744)
	at org.testng.TestRunner.run(TestRunner.java:602)
	at org.testng.SuiteRunner.runTest(SuiteRunner.java:380)
	at org.testng.SuiteRunner.runSequentially(SuiteRunner.java:375)
	at org.testng.SuiteRunner.privateRun(SuiteRunner.java:340)
	at org.testng.SuiteRunner.run(SuiteRunner.java:289)
	at org.testng.SuiteRunnerWorker.runSuite(SuiteRunnerWorker.java:52)
	at org.testng.SuiteRunnerWorker.run(SuiteRunnerWorker.java:86)
	at org.testng.TestNG.runSuitesSequentially(TestNG.java:1301)
	at org.testng.TestNG.runSuitesLocally(TestNG.java:1226)
	at org.testng.TestNG.runSuites(TestNG.java:1144)
	at org.testng.TestNG.run(TestNG.java:1115)
	at org.testng.remote.AbstractRemoteTestNG.run(AbstractRemoteTestNG.java:114)
	at org.testng.remote.RemoteTestNG.initAndRun(RemoteTestNG.java:251)
	at org.testng.remote.RemoteTestNG.main(RemoteTestNG.java:77)
]]>
    </failure>
  </testcase> <!-- CanDoStuff -->
  <testcase name="CanMultiplyX" time="0.001" classname="xray.cloud.test.CalcTest"/>
  <testcase name="CanDivide" time="0.001" classname="xray.cloud.test.CalcTest"/>
  <testcase name="CanAddNumbersFromGivenData" time="0.001" classname="xray.cloud.test.CalcTest">
    <failure type="java.lang.AssertionError" message="expected [4] but found [5]">
      <![CDATA[java.lang.AssertionError: expected [4] but found [5]
	at org.testng.Assert.fail(Assert.java:93)
	at org.testng.Assert.failNotEquals(Assert.java:512)
	at org.testng.Assert.assertEqualsImpl(Assert.java:134)
	at org.testng.Assert.assertEquals(Assert.java:115)
	at org.testng.Assert.assertEquals(Assert.java:388)
	at org.testng.Assert.assertEquals(Assert.java:398)
	at xray.cloud.test.CalcTest.CanAddNumbersFromGivenData(CalcTest.java:40)
	at sun.reflect.NativeMethodAccessorImpl.invoke0(Native Method)
	at sun.reflect.NativeMethodAccessorImpl.invoke(Unknown Source)
	at sun.reflect.DelegatingMethodAccessorImpl.invoke(Unknown Source)
	at java.lang.reflect.Method.invoke(Unknown Source)
	at org.testng.internal.MethodInvocationHelper.invokeMethod(MethodInvocationHelper.java:108)
	at org.testng.internal.Invoker.invokeMethod(Invoker.java:661)
	at org.testng.internal.Invoker.invokeTestMethod(Invoker.java:869)
	at org.testng.internal.Invoker.invokeTestMethods(Invoker.java:1193)
	at org.testng.internal.TestMethodWorker.invokeTestMethods(TestMethodWorker.java:126)
	at org.testng.internal.TestMethodWorker.run(TestMethodWorker.java:109)
	at org.testng.TestRunner.privateRun(TestRunner.java:744)
	at org.testng.TestRunner.run(TestRunner.java:602)
	at org.testng.SuiteRunner.runTest(SuiteRunner.java:380)
	at org.testng.SuiteRunner.runSequentially(SuiteRunner.java:375)
	at org.testng.SuiteRunner.privateRun(SuiteRunner.java:340)
	at org.testng.SuiteRunner.run(SuiteRunner.java:289)
	at org.testng.SuiteRunnerWorker.runSuite(SuiteRunnerWorker.java:52)
	at org.testng.SuiteRunnerWorker.run(SuiteRunnerWorker.java:86)
	at org.testng.TestNG.runSuitesSequentially(TestNG.java:1301)
	at org.testng.TestNG.runSuitesLocally(TestNG.java:1226)
	at org.testng.TestNG.runSuites(TestNG.java:1144)
	at org.testng.TestNG.run(TestNG.java:1115)
	at org.testng.remote.AbstractRemoteTestNG.run(AbstractRemoteTestNG.java:114)
	at org.testng.remote.RemoteTestNG.initAndRun(RemoteTestNG.java:251)
	at org.testng.remote.RemoteTestNG.main(RemoteTestNG.java:77)
]]>
    </failure>
  </testcase> <!-- CanAddNumbersFromGivenData -->
  <testcase name="CanAddNumbersFromGivenData" time="0.002" classname="xray.cloud.test.CalcTest"/>
  <testcase name="CanSubtract" time="0.000" classname="xray.cloud.test.CalcTest"/>
  <testcase name="CanAddNumbers" time="0.006" classname="xray.cloud.test.CalcTest"/>
  <testcase name="CanAddNumbersFromGivenData" time="0.001" classname="xray.cloud.test.CalcTest"/>
</testsuite> <!-- xray.cloud.test.CalcTest -->
